<?xml version="1.0"?>
<robot xmlns:xacro="http://www.ros.org/wiki/xacro" >

<!--Included Files-->
<xacro:include filename="inertial_macros.xacro"/>
   
<xacro:include filename="camera.xacro"/> 


<!--Constants -->
<xacro:property name="platform_radius" value="0.05"/>
<xacro:property name="platform_length" value="0.04"/>
<xacro:property name="tilt_platform_offset" value="0.125"/>
<xacro:property name="pan_platform_offset" value="1.02"/>
<xacro:property name="tilt_mount_pole_radius" value="0.01"/>
<xacro:property name="tilt_mount_pole_offset" value="0.03"/>
<xacro:property name="tilt_mount_pole_length" value="0.1"/>
<xacro:property name="mount_pole_radius" value="0.03"/>



<!--Material Defineitions-->
<material name="white">
    <color rgba="1 1 1 1"/>
</material>

<material name="orange">
    <color rgba="1 0.3 0.1 1"/>
</material>

<material name="blue">
    <color rgba="0.2 0.2 1 1"/>
</material>

<material name="black">
    <color rgba="0 0 0 1"/>
</material>

<!-- Base link -->

<link name="base_link">
</link>

    <!-- BASE_FOOTPRINT LINK -->

    <joint name="base_footprint_joint" type="fixed">
        <parent link="base_link"/>
        <child link="base_footprint"/>
        <origin xyz="0 0 0" rpy="0 0 0"/>
    </joint>

    <link name="base_footprint">
    </link>


<!-- Mounting Pole LINK -->

    <joint name="mounting_pole_joint" type="fixed">
        <parent link="base_link"/>
        <child link="mounting_pole"/>
        <origin xyz="0 0 1"/>
    </joint>

  <link name="mounting_pole">
    <visual>
        <origin xyz = "0 0 0"/>
        <geometry>
            <cylinder length="2" radius="${mount_pole_radius}" />
        </geometry>
        <material name="white"/>
    </visual>

    <collision>
        <origin xyz ="0 0 1"/>
        <geometry>
            <cylinder length="2" radius="${mount_pole_radius}" />
        </geometry>

    </collision>

    <xacro:inertial_cylinder mass = "0.1" length="2" radius="${mount_pole_radius}">
        <origin xyz=" 0 0 -1" rpy="0 0 0"/>
    </xacro:inertial_cylinder>
</link>

<gazebo reference="mounting_pole">
    <material>Gazebo/White</material>
</gazebo>




<!-- Servo Motor Pan Platform (Bottom) -->


<joint name="pan_platform_joint" type="revolute">
    <parent link="mounting_pole"/>
    <child link="pan_platform"/>
    <origin xyz="0 0 ${pan_platform_offset}" rpy="0 0 0"/>
    <axis xyz="0 0 1"/>
   <limit lower = "0" upper ="6.28" velocity = "100" effort="100"/>   
</joint>

<link name="pan_platform">
    <visual>
        <geometry>
            <cylinder length="${platform_length}" radius="${platform_radius}" />
        </geometry>
        <material name="blue"/>
    </visual>

    <collision>
        <geometry>
            <cylinder length="${platform_length}" radius="${platform_radius}" />
        </geometry>

    </collision>

    <xacro:inertial_cylinder mass = "0.1" length="${platform_length}" radius="${platform_radius}">
        <origin xyz=" 0 0 0" rpy="0 0 0"/>
    </xacro:inertial_cylinder>
</link>

<gazebo reference="pan_platform">
    <material>Gazebo/Blue</material>
</gazebo>

<!-- Tilt Mount Pole LINK -->

    <joint name="tilt_mount_pole_joint" type="fixed">
        <parent link="pan_platform"/>
        <child link="tilt_mount_pole"/>
        <origin xyz="0 0 ${tilt_mount_pole_offset}"/>
    </joint>

  <link name="tilt_mount_pole">
    <visual>
        <origin xyz = "0 0 ${tilt_mount_pole_offset}"/>
        <geometry>
            <cylinder length="${tilt_mount_pole_length}" radius="${tilt_mount_pole_radius}" />
        </geometry>
        <material name="white"/>
    </visual>

    <collision>
        <origin xyz ="0 0 ${tilt_mount_pole_offset}"/>
        <geometry>
            <cylinder length="${tilt_mount_pole_length}" radius="${tilt_mount_pole_radius}" />
        </geometry>

    </collision>

    <xacro:inertial_cylinder mass = "0.1" length="${tilt_mount_pole_length}" radius="${tilt_mount_pole_radius}">
        <origin xyz=" 0 0 ${tilt_mount_pole_offset}" rpy="0 0 0"/>
    </xacro:inertial_cylinder>
</link>

<gazebo reference="tilt_mount_pole">
    <material>Gazebo/White</material>
</gazebo>


<!-- Servo Motor Tilt Platform (Bottom) -->

<joint name="tilt_platform_joint" type="revolute">
    <parent link="tilt_mount_pole"/>
    <child link="tilt_platform"/>

    <origin xyz="0 0 ${tilt_platform_offset}" rpy="-${pi/2} 0 0"/>
    <axis xyz = "0 0 -1"/>
    <limit lower = "-0.78" upper ="1.57" velocity = "100" effort="100"/>
   
</joint>

<link name="tilt_platform">
    <visual>
        <geometry>
            <cylinder length="${platform_length}" radius="${platform_radius}" />
        </geometry>
        <material name="orange"/>
    </visual>

    <collision>
        <geometry>
            <cylinder length="${platform_length}" radius="${platform_radius}" />
        </geometry>
    </collision>

    <xacro:inertial_cylinder mass = "0.1" length="${platform_length}" radius="${platform_radius}">
        <origin xyz=" 0 0 0" rpy="0 0 0"/>
    </xacro:inertial_cylinder>
    
</link>

<gazebo reference="tilt_platform">
    <material>Gazebo/Orange</material>
</gazebo>




</robot>
